Workbook

Sheet Exercise
B2: รายงานแสดงจำนวนนิสิต จำแนกตามหมู่เรียน ภาคต้น ปีการศึกษา 2569
B3: มหาวิทยาลัยเกษตรศาสตร์ บางเขน ระดับการศึกษา ปริญญาตรี
B4: ชื่อวิชา | C4: 01218332-65 การฉายแผนที่ Map Projection | M4: รศ.ดร.ไพศาล สันติธรรมนนท์
E5: หมู่เรียน | F5: 250 - บรรยาย | G5: 2 หน่วยกิต
B6: รายชื่อนิสิต | G6: สรุปทั้งหมด 46 คน สถานะ Drop ติด W 0 คน | L6: Ex.2 Intro to Geodesy | M6: EX.3 Draw Sphere/Spheroid | N6: Ex.4 EFG for Sphere | O6: Ex.5 Guassian vs Mercator | P6: Ex.6 Tissot Indicator | Q6: MidTerm Exam | R6: Ex.7 Lambert Conformal Conic | S6: Ex.8 Planar Map Projection | T6: Ex.9 Mercator vs EqualEarth | U6: Ex.10 UTM zone 47/48 | V6: Ex.11 LDP | W6: Ex.12 WebMap | X6: Final Exam
B7: ลำดับที่ | C7: รหัสนิสิต | D7: ชื่อ-นามสกุล | E7: ชื่อ-นามสกุล | F7: คณะ/หน่วยงานที่เทียบเท่า | G7: สาขาวิชา | H7: รหัสสาขา | I7: สถานะ | J7: Email Google | K7: Email Office365 | L7: 12 | M7: 10 | N7: 10 | O7: 10 | P7: 10 | Q7: 26 | R7: 10 | S7: 10 | T7: 10 | U7: 10 | V7: 10
B8: 1 | C8: 6610553157 | D8: นายธีรพัส แก้วงาม | E8: Mr. Theerapat KEAONGAM | F8: วิศวกรรมศาสตร์ | G8: วิศวกรรมสำรวจและสารสนเทศภูมิศาสตร์ | H8: E18 | I8: 25 | J8: theerapat.ke@ku.th | K8: theerapat.ke@live.ku.th | N8: 8 | P8: 8 | Q8: 10 | R8: 5 | T8: 7 | U8: 9 | V8: 3
B9: 2 | C9: 6610553165 | D9: นางสาวนภัสสร นูมหันต์ | E9: Miss Naphatson NUMAHAN | F9: วิศวกรรมศาสตร์ | G9: วิศวกรรมสำรวจและสารสนเทศภูมิศาสตร์ | H9: E18 | I9: 25 | J9: naphatson.nu@ku.th | K9: naphatson.nu@live.ku.th | M9: 3 | O9: 10 | Q9: 4 | R9: 10 | S9: 10 | T9: 7 | U9: 9 | V9: 9
B10: 3 | C10: 6610553173 | D10: นางสาวนรภร เจริญสลุง | E10: Miss Naraporn JAROENSALUNG | F10: วิศวกรรมศาสตร์ | G10: วิศวกรรมสำรวจและสารสนเทศภูมิศาสตร์ | H10: E18 | I10: 25 | J10: naraporn.ja@ku.th | K10: naraporn.ja@live.ku.th | M10: 3 | O10: 5 | P10: 8 | Q10: 4 | S10: 10 | T10: 10 | U10: 10 | V10: 0
B11: 4 | C11: 6610553181 | D11: นายบุนยามีน มะสง | E11: Mr. Bunyamin MASONG | F11: วิศวกรรมศาสตร์ | G11: วิศวกรรมสำรวจและสารสนเทศภูมิศาสตร์ | H11: E18 | I11: 25 | J11: bunyamin.m@ku.th | K11: bunyamin.m@live.ku.th | L11: 11 | M11: 3 | N11: 7 | O11: 5 | P11: 9 | Q11: 9 | R11: 10 | S11: 10 | T11: 7 | U11: 7 | V11: 6
B12: 5 | C12: 6610553203 | D12: นายปัญญานันท์ ทองแก้วเกิด | E12: Mr. Panyanan THONGKAEWKOED | F12: วิศวกรรมศาสตร์ | G12: วิศวกรรมสำรวจและสารสนเทศภูมิศาสตร์ | H12: E18 | I12: 25 | J12: panyanan.t@ku.th | K12: panyanan.t@live.ku.th | N12: 7 | P12: 10 | Q12: 9 | R12: 10 | S12: 10 | T12: 7 | U12: 8
B13: 6 | C13: 6610553220 | D13: นางสาวภิญยดา ศรีแนน | E13: Miss PHINYADA SRINAN | F13: วิศวกรรมศาสตร์ | G13: วิศวกรรมสำรวจและสารสนเทศภูมิศาสตร์ | H13: E18 | I13: 25 | J13: phinyada.sr@ku.th | K13: phinyada.sr@live.ku.th | Q13: 0 | R13: 5 | S13: 10 | T13: 5 | U13: 9
B14: 7 | C14: 6610553238 | D14: นายภูริณ มานหมัด | E14: Mr. Purin MARNMAAD | F14: วิศวกรรมศาสตร์ | G14: วิศวกรรมสำรวจและสารสนเทศภูมิศาสตร์ | H14: E18 | I14: 25 | J14: purin.m@ku.th | K14: purin.m@live.ku.th | M14: 4 | O14: 5 | P14: 8 | Q14: 2 | R14: 10 | S14: 3 | T14: 7 | U14: 7 | V14: 10
B15: 8 | C15: 6610553254 | D15: นายรัชชานนท์ สาคะเรศ | E15: Mr. Ratchanon SAKHARET | F15: วิศวกรรมศาสตร์ | G15: วิศวกรรมสำรวจและสารสนเทศภูมิศาสตร์ | H15: E18 | I15: 25 | J15: ratchanon.sakh@ku.th | K15: ratchanon.sakh@live.ku.th | L15: 12 | M15: 2 | N15: 8 | O15: 5 | P15: 8 | Q15: 11 | R15: 8 | S15: 8 | T15: 6 | U15: 7 | V15: 9
B16: 9 | C16: 6610553262 | D16: นายวรพล พลอยชัด | E16: Mr. Worapon PLOYCHAT | F16: วิศวกรรมศาสตร์ | G16: วิศวกรรมสำรวจและสารสนเทศภูมิศาสตร์ | H16: E18 | I16: 25 | J16: worapon.pl@ku.th | K16: worapon.pl@live.ku.th | M16: 7 | N16: 10 | O16: 5 | Q16: 14 | R16: 3 | S16: 10 | T16: 7 | U16: 6 | V16: 6
B17: 10 | C17: 6610553271 | D17: นายศุภณัฐ จันทรังษี | E17: Mr. Suphanat CHANTHARANGSI | F17: วิศวกรรมศาสตร์ | G17: วิศวกรรมสำรวจและสารสนเทศภูมิศาสตร์ | H17: E18 | I17: 25 | J17: suphanat.chan@ku.th | K17: suphanat.chan@live.ku.th | L17: 12 | M17: 3 | N17: 8 | O17: 5 | P17: 10 | Q17: 9 | R17: 10 | S17: 10 | T17: 7 | U17: 6 | V17: 10
B18: 11 | C18: 6610553289 | D18: นางสาวเศรษฐกมล วังออมทรัพย์ | E18: Miss Settakamol WANG-OOMSAP | F18: วิศวกรรมศาสตร์ | G18: วิศวกรรมสำรวจและสารสนเทศภูมิศาสตร์ | H18: E18 | I18: 25 | J18: settakamol.wa@ku.th | K18: settakamol.wa@live.ku.th | M18: 5 | O18: 5 | P18: 9 | Q18: 2 | R18: 10 | S18: 10 | T18: 6 | U18: 10
B19: 12 | C19: 6610553327 | D19: นางสาวอริศรา เล่งกูล | E19: Miss Arisara LENGKOON | F19: วิศวกรรมศาสตร์ | G19: วิศวกรรมสำรวจและสารสนเทศภูมิศาสตร์ | H19: E18 | I19: 25 | J19: arisara.len@ku.th | K19: arisara.len@live.ku.th | Q19: 0 | R19: 10 | S19: 10 | T19: 7 | U19: 7
B20: 13 | C20: 6610554153 | D20: นายภัทรพล ดิษฐาพร | E20: Mr. Pattarapon DITTHAPHON | F20: วิศวกรรมศาสตร์ | G20: วิศวกรรมสำรวจและสารสนเทศภูมิศาสตร์ | H20: E18 | I20: 25 | J20: pattarapon.ditt@ku.th | K20: pattarapon.ditt@live.ku.th | L20: 12 | M20: 4 | N20: 9 | O20: 5 | P20: 10 | Q20: 5 | R20: 5 | T20: 7 | U20: 7 | V20: 0
B21: 14 | C21: 6610554161 | D21: นายภาคิน แซ่โง้ว | E21: Mr. Pakin SAENGOW | F21: วิศวกรรมศาสตร์ | G21: วิศวกรรมสำรวจและสารสนเทศภูมิศาสตร์ | H21: E18 | I21: 25 | J21: pakin.saen@ku.th | K21: pakin.saen@live.ku.th | L21: 12 | M21: 5 | O21: 5 | Q21: 6 | S21: 10 | T21: 8 | U21: 8
B22: 15 | C22: 6710552942 | D22: นายกนล แสงเดช | E22: Mr. Kanol SAENGDECH | F22: วิศวกรรมศาสตร์ | G22: วิศวกรรมสำรวจและสารสนเทศภูมิศาสตร์ | H22: E18 | I22: 25 | J22: kanol.s@ku.th | K22: kanol.s@live.ku.th | L22: 10 | M22: 7 | N22: 7 | O22: 10 | P22: 10 | Q22: 2 | R22: 10 | S22: 9 | T22: 7 | U22: 10 | V22: 0
B23: 16 | C23: 6710552951 | D23: นางสาวกมลนิตย์ โตอยู่ | E23: Miss Kamonnit THOYU | F23: วิศวกรรมศาสตร์ | G23: วิศวกรรมสำรวจและสารสนเทศภูมิศาสตร์ | H23: E18 | I23: 25 | J23: kamonnit.t@ku.th | K23: kamonnit.t@live.ku.th | L23: 8 | M23: 7 | N23: 10 | O23: 10 | P23: 10 | Q23: 16 | R23: 10 | S23: 10 | T23: 10 | U23: 10 | V23: 0
B24: 17 | C24: 6710552969 | D24: นายกฤษกร ศรีสัจจัง | E24: Mr. Krisskon SRISAJJANG | F24: วิศวกรรมศาสตร์ | G24: วิศวกรรมสำรวจและสารสนเทศภูมิศาสตร์ | H24: E18 | I24: 25 | J24: krisskon.s@ku.th | K24: krisskon.s@live.ku.th | L24: 11 | M24: 10 | N24: 7 | O24: 10 | P24: 10 | Q24: 12 | R24: 10 | S24: 10 | T24: 10 | U24: 10 | V24: 0
B25: 18 | C25: 6710552977 | D25: นายกันติวัสส์ ตันตระการย์ | E25: Mr. Kantiwat TANTRAKARN | F25: วิศวกรรมศาสตร์ | G25: วิศวกรรมสำรวจและสารสนเทศภูมิศาสตร์ | H25: E18 | I25: 25 | J25: kantiwat.ta@ku.th | K25: kantiwat.ta@live.ku.th | L25: 6 | M25: 7 | N25: 7 | O25: 5 | P25: 10 | Q25: 9 | R25: 10 | S25: 5 | T25: 7 | U25: 8 | V25: 0
B26: 19 | C26: 6710552985 | D26: นายเกษมโชค นชะพงษ์ | E26: Mr. Kasemchoke NACHAPONG | F26: วิศวกรรมศาสตร์ | G26: วิศวกรรมสำรวจและสารสนเทศภูมิศาสตร์ | H26: E18 | I26: 25 | J26: kasemchoke.na@ku.th | K26: kasemchoke.na@live.ku.th | L26: 12 | M26: 5 | N26: 10 | O26: 10 | P26: 10 | Q26: 1 | R26: 10 | S26: 10 | T26: 8 | U26: 8 | V26: 10
B27: 20 | C27: 6710552993 | D27: นายจักรินทร์ อินทร์น้อย | E27: Mr. Jakkarin INNOI | F27: วิศวกรรมศาสตร์ | G27: วิศวกรรมสำรวจและสารสนเทศภูมิศาสตร์ | H27: E18 | I27: 25 | J27: jakkarin.in@ku.th | K27: jakkarin.in@live.ku.th | L27: 7 | M27: 5 | O27: 10 | P27: 10 | Q27: 1 | R27: 10 | S27: 10 | T27: 8 | U27: 10 | V27: 10
B28: 21 | C28: 6710553001 | D28: นางสาวจันทร์เจ้า เทพจิตต์ | E28: Miss CHANCHAO THEPJIT | F28: วิศวกรรมศาสตร์ | G28: วิศวกรรมสำรวจและสารสนเทศภูมิศาสตร์ | H28: E18 | I28: 25 | J28: chanchao.t@ku.th | K28: chanchao.t@live.ku.th | L28: 7 | N28: 7 | O28: 4 | Q28: 8 | R28: 10 | S28: 10 | V28: 7
B29: 22 | C29: 6710553027 | D29: นางสาวฑิฆัมพร ตรีบุสยะรัตน์ | E29: Miss TIKAMPORN TREEBUSAYARAT | F29: วิศวกรรมศาสตร์ | G29: วิศวกรรมสำรวจและสารสนเทศภูมิศาสตร์ | H29: E18 | I29: 25 | J29: tikamporn.tr@ku.th | K29: tikamporn.tr@live.ku.th | L29: 6 | M29: 8 | N29: 10 | O29: 10 | P29: 10 | Q29: 9 | R29: 10 | S29: 10 | T29: 10 | U29: 10 | V29: 0
B30: 23 | C30: 6710553035 | D30: นางสาวณปภัช บุญมายศ | E30: Miss NAPAPACH BUNMAYOS | F30: วิศวกรรมศาสตร์ | G30: วิศวกรรมสำรวจและสารสนเทศภูมิศาสตร์ | H30: E18 | I30: 25 | J30: napapach.bu@ku.th | K30: napapach.bu@live.ku.th | L30: 12 | M30: 10 | N30: 10 | O30: 10 | P30: 10 | Q30: 11 | R30: 10 | S30: 10 | T30: 8 | U30: 10 | V30: 0
B31: 24 | C31: 6710553051 | D31: นายธนทัต มุทธากาญจน์ | E31: Mr. Tanatud MUTTAKARN | F31: วิศวกรรมศาสตร์ | G31: วิศวกรรมสำรวจและสารสนเทศภูมิศาสตร์ | H31: E18 | I31: 25 | J31: tanatud.m@ku.th | K31: tanatud.m@live.ku.th
B32: 25 | C32: 6710553078 | D32: นายธนภูมิ เหลืองชัยพัฒนา | E32: Mr. Thanaphum LUANGCHAIPATTANA | F32: วิศวกรรมศาสตร์ | G32: วิศวกรรมสำรวจและสารสนเทศภูมิศาสตร์ | H32: E18 | I32: 25 | J32: thanaphum.l@ku.th | K32: thanaphum.l@live.ku.th | L32: 12 | M32: 9 | N32: 10 | O32: 10 | P32: 10 | Q32: 14 | R32: 5 | S32: 10 | T32: 7 | U32: 7 | V32: 6
B33: 26 | C33: 6710553086 | D33: นายธนากร เรืองพูน | E33: Mr. Thanakon RUEANGPHUN | F33: วิศวกรรมศาสตร์ | G33: วิศวกรรมสำรวจและสารสนเทศภูมิศาสตร์ | H33: E18 | I33: 25 | J33: thanakon.r@ku.th | K33: thanakon.r@live.ku.th | L33: 5 | M33: 10 | O33: 10 | P33: 10 | Q33: 3 | R33: 10 | S33: 10 | U33: 10 | V33: 10
B34: 27 | C34: 6710553094 | D34: นายธรรมกร เจริญพร | E34: Mr. THAMMAKORN CHAROENPORN | F34: วิศวกรรมศาสตร์ | G34: วิศวกรรมสำรวจและสารสนเทศภูมิศาสตร์ | H34: E18 | I34: 25 | J34: thammakorn.c@ku.th | K34: thammakorn.c@live.ku.th | L34: 12 | M34: 8 | N34: 10 | O34: 10 | P34: 10 | Q34: 25 | R34: 10 | S34: 10 | T34: 7 | U34: 10 | V34: 7
B35: 28 | C35: 6710553108 | D35: นางสาวธัชตะวัน ยกโต | E35: Miss Thattawan YOKTO | F35: วิศวกรรมศาสตร์ | G35: วิศวกรรมสำรวจและสารสนเทศภูมิศาสตร์ | H35: E18 | I35: 25 | J35: thattawan.y@ku.th | K35: thattawan.y@live.ku.th | L35: 8 | M35: 10 | N35: 10 | O35: 10 | P35: 10 | Q35: 17 | R35: 7 | S35: 10 | T35: 7 | U35: 9 | V35: 0
B36: 29 | C36: 6710553124 | D36: นายนนทกร จวนทองรักษ์ | E36: Mr. Nonthakorn JAUNTHONGRAK | F36: วิศวกรรมศาสตร์ | G36: วิศวกรรมสำรวจและสารสนเทศภูมิศาสตร์ | H36: E18 | I36: 25 | J36: nonthakorn.j@ku.th | K36: nonthakorn.j@live.ku.th | L36: 12 | M36: 8 | N36: 7 | O36: 10 | P36: 10 | Q36: 7 | R36: 10 | S36: 10 | T36: 7 | U36: 7 | V36: 10
B37: 30 | C37: 6710553141 | D37: นายนภัสรพี อร่ามฉิม | E37: Mr. Naputrapee ARAMCHIM | F37: วิศวกรรมศาสตร์ | G37: วิศวกรรมสำรวจและสารสนเทศภูมิศาสตร์ | H37: E18 | I37: 25 | J37: naputrapee.a@ku.th | K37: naputrapee.a@live.ku.th | L37: 11 | M37: 8 | N37: 10 | O37: 10 | P37: 9 | Q37: 17 | R37: 10 | S37: 10 | T37: 7 | U37: 6 | V37: 0
B38: 31 | C38: 6710553167 | D38: นายพิชญุตม์ ลอยมา | E38: Mr. PICHAYUT LOYMA | F38: วิศวกรรมศาสตร์ | G38: วิศวกรรมสำรวจและสารสนเทศภูมิศาสตร์ | H38: E18 | I38: 25 | J38: pichayut.l@ku.th | K38: pichayut.l@live.ku.th | M38: 5 | N38: 10 | O38: 5 | P38: 10 | Q38: 16 | R38: 5 | S38: 10 | T38: 7 | U38: 8 | V38: 0
B39: 32 | C39: 6710553191 | D39: นายภควัฒน์ พรมประโคน | E39: Mr. PAKHAWAT PROMPRAKHON | F39: วิศวกรรมศาสตร์ | G39: วิศวกรรมสำรวจและสารสนเทศภูมิศาสตร์ | H39: E18 | I39: 25 | J39: pakhawat.p@ku.th | K39: pakhawat.p@live.ku.th | L39: 12 | M39: 10 | N39: 10 | O39: 10 | P39: 10 | Q39: 22 | R39: 10 | S39: 10 | T39: 10 | U39: 10 | V39: 10
B40: 33 | C40: 6710553205 | D40: นายภัคพล ลาวชัย | E40: Mr. Phakkaphon LAOCHAI | F40: วิศวกรรมศาสตร์ | G40: วิศวกรรมสำรวจและสารสนเทศภูมิศาสตร์ | H40: E18 | I40: 25 | J40: phakkaphon.l@ku.th | K40: phakkaphon.l@live.ku.th | L40: 11 | M40: 9 | N40: 9 | O40: 10 | P40: 10 | Q40: 15 | R40: 5 | S40: 10 | T40: 7 | U40: 10 | V40: 8
B41: 34 | C41: 6710553213 | D41: นายภัคพล อินทะรังษี | E41: Mr. Pakkapon INTARUNGSRI | F41: วิศวกรรมศาสตร์ | G41: วิศวกรรมสำรวจและสารสนเทศภูมิศาสตร์ | H41: E18 | I41: 25 | J41: pakkapon.i@ku.th | K41: pakkapon.i@live.ku.th | L41: 10 | M41: 9 | N41: 10 | O41: 10 | P41: 10 | Q41: 6 | R41: 5 | S41: 10 | T41: 7 | U41: 10 | V41: 0
...

Sheet ClassAttend
C6: การเข้าเรียน | D6: 04-14JUL69 | E6: 05-20JUL69 | F6: 06-10/8/1969 | G6: 46258 | H6: 46265 | I6: 25460 | J6: 21/Sept/2569 | K6: 46307
A7: =Exercise!B7 | B7: =Exercise!C7 | C7: =Exercise!D7 | D7: 1 | E7: 1 | F7: 1 | G7: 1 | H7: 1 | I7: 1 | J7: 1 | K7: 1
A8: =Exercise!B8 | B8: =Exercise!C8 | C8: =Exercise!D8 | D8: 1 | F8: 1 | H8: 1 | J8: 1 | K8: 1
A9: =Exercise!B9 | B9: =Exercise!C9 | C9: =Exercise!D9 | E9: 1 | G9: 1 | H9: 1 | I9: 1 | J9: 1 | K9: 1
A10: =Exercise!B10 | B10: =Exercise!C10 | C10: =Exercise!D10 | E10: 1 | H10: 1 | J10: 1 | K10: 1
A11: =Exercise!B11 | B11: =Exercise!C11 | C11: =Exercise!D11 | D11: 1 | E11: 1 | F11: 1 | G11: 1 | H11: 1 | I11: 1 | J11: 1 | K11: 1
A12: =Exercise!B12 | B12: =Exercise!C12 | C12: =Exercise!D12 | D12: 1 | E12: 1 | F12: 1 | G12: 1 | H12: 1 | I12: 1 | J12: 1
A13: =Exercise!B13 | B13: =Exercise!C13 | C13: =Exercise!D13 | E13: 1 | G13: 1 | H13: 1 | I13: 1 | J13: 1
A14: =Exercise!B14 | B14: =Exercise!C14 | C14: =Exercise!D14 | D14: 1 | F14: 1 | G14: 1 | I14: 1 | J14: 1 | K14: 1
A15: =Exercise!B15 | B15: =Exercise!C15 | C15: =Exercise!D15 | D15: 1 | E15: 1 | F15: 1 | G15: 1 | H15: 1 | I15: 1 | J15: 1 | K15: 1
A16: =Exercise!B16 | B16: =Exercise!C16 | C16: =Exercise!D16 | D16: 1 | E16: 1 | F16: 1 | G16: 1 | H16: 1 | I16: 1 | J16: 1
A17: =Exercise!B17 | B17: =Exercise!C17 | C17: =Exercise!D17 | D17: 1 | E17: 1 | F17: 1 | G17: 1 | H17: 1 | I17: 1 | J17: 1 | K17: 1
A18: =Exercise!B18 | B18: =Exercise!C18 | C18: =Exercise!D18 | E18: 1 | F18: 1 | G18: 1 | H18: 1 | I18: 1 | J18: 1 | K18: 1
A19: =Exercise!B19 | B19: =Exercise!C19 | C19: =Exercise!D19 | E19: 1 | G19: 1 | H19: 1 | I19: 1 | J19: 1
A20: =Exercise!B20 | B20: =Exercise!C20 | C20: =Exercise!D20 | F20: 1 | G20: 1 | H20: 1 | I20: 1 | J20: 1 | K20: 1
A21: =Exercise!B21 | B21: =Exercise!C21 | C21: =Exercise!D21 | D21: 1 | E21: 1 | J21: 1
A22: =Exercise!B22 | B22: =Exercise!C22 | C22: =Exercise!D22 | D22: 1 | E22: 1 | F22: 1 | G22: 1 | H22: 1 | I22: 1 | K22: 1
A23: =Exercise!B23 | B23: =Exercise!C23 | C23: =Exercise!D23 | D23: 1 | E23: 1 | F23: 1 | G23: 1 | H23: 1 | I23: 1 | J23: 1 | K23: 1
A24: =Exercise!B24 | B24: =Exercise!C24 | C24: =Exercise!D24 | D24: 1 | E24: 1 | F24: 1 | G24: 1 | H24: 1 | I24: 1 | J24: 1 | K24: 1
A25: =Exercise!B25 | B25: =Exercise!C25 | C25: =Exercise!D25 | D25: 1 | E25: 1 | F25: 1 | G25: 1 | H25: 1 | I25: 1 | J25: 1 | K25: 1
A26: =Exercise!B26 | B26: =Exercise!C26 | C26: =Exercise!D26 | D26: 1 | E26: 1 | F26: 1 | G26: 1 | H26: 1 | I26: 1 | J26: 1 | K26: 1
A27: =Exercise!B27 | B27: =Exercise!C27 | C27: =Exercise!D27 | E27: 1 | F27: 1 | G27: 1 | H27: 1 | I27: 1 | J27: 1 | K27: 1
A28: =Exercise!B28 | B28: =Exercise!C28 | C28: =Exercise!D28 | E28: 1 | F28: 1 | G28: 1 | I28: 1 | K28: 1
A29: =Exercise!B29 | B29: =Exercise!C29 | C29: =Exercise!D29 | D29: 1 | E29: 1 | F29: 1 | G29: 1 | H29: 1 | I29: 1 | J29: 1 | K29: 1
A30: =Exercise!B30 | B30: =Exercise!C30 | C30: =Exercise!D30 | D30: 1 | E30: 1 | F30: 1 | G30: 1 | H30: 1 | I30: 1 | J30: 1 | K30: 1
A31: =Exercise!B31 | B31: =Exercise!C31 | C31: =Exercise!D31
A32: =Exercise!B32 | B32: =Exercise!C32 | C32: =Exercise!D32 | D32: 1 | E32: 1 | F32: 1 | G32: 1 | H32: 1 | I32: 1 | J32: 1 | K32: 1
A33: =Exercise!B33 | B33: =Exercise!C33 | C33: =Exercise!D33 | E33: 1 | F33: 1 | G33: 1 | H33: 1 | I33: 1 | J33: 1 | K33: 1
A34: =Exercise!B34 | B34: =Exercise!C34 | C34: =Exercise!D34 | D34: 1 | E34: 1 | F34: 1 | G34: 1 | H34: 1 | I34: 1 | J34: 1 | K34: 1
A35: =Exercise!B35 | B35: =Exercise!C35 | C35: =Exercise!D35 | D35: 1 | E35: 1 | F35: 1 | G35: 1 | H35: 1 | I35: 1 | J35: 1 | K35: 1
A36: =Exercise!B36 | B36: =Exercise!C36 | C36: =Exercise!D36 | D36: 1 | E36: 1 | F36: 1 | G36: 1 | I36: 1 | J36: 1 | K36: 1
A37: =Exercise!B37 | B37: =Exercise!C37 | C37: =Exercise!D37 | D37: 1 | E37: 1 | F37: 1 | G37: 1 | H37: 1 | I37: 1 | J37: 1 | K37: 1
A38: =Exercise!B38 | B38: =Exercise!C38 | C38: =Exercise!D38 | D38: 1 | F38: 1 | G38: 1 | H38: 1 | I38: 1 | J38: 1 | K38: 1
A39: =Exercise!B39 | B39: =Exercise!C39 | C39: =Exercise!D39 | D39: 1 | E39: 1 | F39: 1 | G39: 1 | H39: 1 | I39: 1 | J39: 1 | K39: 1
A40: =Exercise!B40 | B40: =Exercise!C40 | C40: =Exercise!D40 | D40: 1 | E40: 1 | F40: 1 | G40: 1 | H40: 1 | I40: 1 | K40: 1
A41: =Exercise!B41 | B41: =Exercise!C41 | C41: =Exercise!D41 | D41: 1 | E41: 1 | F41: 1 | G41: 1 | H41: 1 | I41: 1 | J41: 1 | K41: 1
A42: =Exercise!B42 | B42: =Exercise!C42 | C42: =Exercise!D42 | D42: 1 | E42: 1 | F42: 1 | G42: 1 | H42: 1 | I42: 1 | J42: 1 | K42: 1
A43: =Exercise!B43 | B43: =Exercise!C43 | C43: =Exercise!D43 | D43: 1 | E43: 1 | F43: 1 | G43: 1 | H43: 1 | I43: 1 | J43: 1 | K43: 1
A44: =Exercise!B44 | B44: =Exercise!C44 | C44: =Exercise!D44 | D44: 1 | E44: 1 | F44: 1 | G44: 1 | H44: 1 | I44: 1 | J44: 1 | K44: 1
A45: =Exercise!B45 | B45: =Exercise!C45 | C45: =Exercise!D45 | D45: 1 | E45: 1 | F45: 1 | G45: 1 | H45: 1 | I45: 1 | J45: 1 | K45: 1
...

Sheet Summary
A1: No. | B1: Student ID | C1: Name | D1: Exercise Raw | E1: Exercise % | F1: Exercise 70% | G1: Attendance | H1: Attendance % | I1: Attendance 30% | J1: Grand Total | K1: Performance
A2: 1 | B2: 6610553157 | C2: ---- | D2: 50.00/128.00 | E2: 39.0625 | F2: 27.34375 | G2: 5/8 | H2: 62.5 | I2: 18.75 | J2: 46.09375 | K2: ★☆☆☆☆
A3: 2 | B3: 6610553165 | C3: ---- | D3: 62.00/128.00 | E3: 48.4375 | F3: 33.90625 | G3: 6/8 | H3: 75 | I3: 22.5 | J3: 56.40625 | K3: ★☆☆☆☆
A4: 3 | B4: 6610553173 | C4: ---- | D4: 50.00/128.00 | E4: 39.0625 | F4: 27.34375 | G4: 4/8 | H4: 50 | I4: 15 | J4: 42.34375 | K4: ★☆☆☆☆
A5: 4 | B5: 6610553181 | C5: ---- | D5: 84.00/128.00 | E5: 65.625 | F5: 45.9375 | G5: 8/8 | H5: 100 | I5: 30 | J5: 75.9375 | K5: ★★★☆☆
A6: 5 | B6: 6610553203 | C6: ---- | D6: 61.00/128.00 | E6: 47.65625 | F6: 33.359375 | G6: 7/8 | H6: 87.5 | I6: 26.25 | J6: 59.609375 | K6: ★☆☆☆☆
A7: 6 | B7: 6610553220 | C7: ---- | D7: 29.00/128.00 | E7: 22.65625 | F7: 15.859375 | G7: 5/8 | H7: 62.5 | I7: 18.75 | J7: 34.609375 | K7: ★☆☆☆☆
A8: 7 | B8: 6610553238 | C8: ---- | D8: 56.00/128.00 | E8: 43.75 | F8: 30.625 | G8: 6/8 | H8: 75 | I8: 22.5 | J8: 53.125 | K8: ★☆☆☆☆
A9: 8 | B9: 6610553254 | C9: ---- | D9: 84.00/128.00 | E9: 65.625 | F9: 45.9375 | G9: 8/8 | H9: 100 | I9: 30 | J9: 75.9375 | K9: ★★★☆☆
A10: 9 | B10: 6610553262 | C10: ---- | D10: 68.00/128.00 | E10: 53.125 | F10: 37.1875 | G10: 7/8 | H10: 87.5 | I10: 26.25 | J10: 63.4375 | K10: ★★☆☆☆
A11: 10 | B11: 6610553271 | C11: ---- | D11: 90.00/128.00 | E11: 70.3125 | F11: 49.21875 | G11: 8/8 | H11: 100 | I11: 30 | J11: 79.21875 | K11: ★★★☆☆
A12: 11 | B12: 6610553289 | C12: ---- | D12: 57.00/128.00 | E12: 44.53125 | F12: 31.171875 | G12: 7/8 | H12: 87.5 | I12: 26.25 | J12: 57.421875 | K12: ★☆☆☆☆
A13: 12 | B13: 6610553327 | C13: ---- | D13: 34.00/128.00 | E13: 26.5625 | F13: 18.59375 | G13: 5/8 | H13: 62.5 | I13: 18.75 | J13: 37.34375 | K13: ★☆☆☆☆
... A47: 46 | B47: 6710553396 | C47: ---- | D47: 114.00/128.00 | E47: 89.0625 | F47: 62.34375 | G47: 8/8 | H47: 100 | I47: 30 | J47: 92.34375 | K47: ★★★★★
A50: Exercise maximum score | B50: 128
A51: Exercise weight | B51: 0.7
A52: Attendance sessions | B52: 8
A53: Attendance weight | B53: 0.3
A55: Total students | B55: 46
A56: Mean Grand Total | B56: 70.319293
A57: SD Grand Total (population) | B57: 18.952252
